Workbook
Name 유효성검사: OFFSET(#REF!,,,COUNTIF(#REF!,"*?"))

Sheet MAIN
C1: 견적서 | N1: ㅇ견적내용
K2: 견적일 | L2: =TODAY() -> 46231
D3: 공급자 정보. | H3: 고객 정보.
H4: 성함
D5: 비에스비인터내셔널 (퍼커션센터) 대표자 조익환 | H5: 연락처
D6: 488-81-02809 | F6: (인) | H6: 주소
D7: percussion.cs@gmail.com
D8: 담당 전인철 실장 010-4311-3604 | H8: 이메일
D9: 서울시 서초구 양재동 392-10 정암빌딩 지하 | H9: 비고 | O9: 상품명 검색
D11: 견적금액 (VAT포함) | F11: =TEXT(K11,"[DBNum4]")&" 원정" -> 영 원정 | K11: =L30 -> 0
A13: 공급 | B13: 매입처 | D13: 분류 | E13: 브랜드 | F13: 제품 설명 | G13: 모델명 | H13: 수량 | I13: 소비자가 | J13: 소비자가합계 | K13: 판매단가 | L13: 총 판매가 | N13: 판매가 | O13: 매입가 | P13: 배송비 | Q13: 최저가 | R13: 총매입가 | S13: 마진 | T13: 마진율
A14: =IFERROR(_xlfn.XLOOKUP($G14,[1]재고!$D:$D,[1]재고!$A:$A,0),"") -> 0 | D14: =IFERROR(_xlfn.XLOOKUP($G14,[1]재고!$D:$D,[1]재고!$B:$B,0),"") -> 0 | E14: =IFERROR(_xlfn.XLOOKUP($G14,[1]재고!$D:$D,[1]재고!$C:$C,0),"") -> 0 | F14: =IFERROR(_xlfn.XLOOKUP($G14,[1]재고!$D:$D,[1]재고!$G:$G,0),"") -> 0 | I14: =IFERROR(_xlfn.XLOOKUP($G14,[1]재고!$D:$D,[1]재고!$F:$F,0),"") -> 0 | J14: =I14*H14 -> 0 | K14: =ROUNDUP(N14,-3) -> 0 | L14: =H14*K14 -> 0 | O14: =IFERROR(_xlfn.XLOOKUP($G14,[1]재고!$D:$D,[1]재고!$E:$E,0),"") -> 0 | R14: =O14*H14+P14 -> 0 | S14: =L14-R14 -> 0 | T14: =N14/O14-1 -> #DIV/0!
A15: =IFERROR(_xlfn.XLOOKUP($G15,[1]재고!$D:$D,[1]재고!$A:$A,0),"") -> 0 | D15: =IFERROR(_xlfn.XLOOKUP($G15,[1]재고!$D:$D,[1]재고!$B:$B,0),"") -> 0 | E15: =IFERROR(_xlfn.XLOOKUP($G15,[1]재고!$D:$D,[1]재고!$C:$C,0),"") -> 0 | F15: =IFERROR(_xlfn.XLOOKUP($G15,[1]재고!$D:$D,[1]재고!$G:$G,0),"") -> 0 | I15: =IFERROR(_xlfn.XLOOKUP($G15,[1]재고!$D:$D,[1]재고!$F:$F,0),"") -> 0 | J15: =I15*H15 -> 0 | K15: =ROUNDUP(N15,-3) -> 0 | L15: =H15*K15 -> 0 | O15: =IFERROR(_xlfn.XLOOKUP($G15,[1]재고!$D:$D,[1]재고!$E:$E,0),"") -> 0 | R15: =O15*H15+P15 -> 0 | S15: =L15-R15 -> 0 | T15: =N15/O15-1 -> #DIV/0!
A16: =IFERROR(_xlfn.XLOOKUP($G16,[1]재고!$D:$D,[1]재고!$A:$A,0),"") -> 0 | D16: =IFERROR(_xlfn.XLOOKUP($G16,[1]재고!$D:$D,[1]재고!$B:$B,0),"") -> 0 | E16: =IFERROR(_xlfn.XLOOKUP($G16,[1]재고!$D:$D,[1]재고!$C:$C,0),"") -> 0 | F16: =IFERROR(_xlfn.XLOOKUP($G16,[1]재고!$D:$D,[1]재고!$G:$G,0),"") -> 0 | I16: =IFERROR(_xlfn.XLOOKUP($G16,[1]재고!$D:$D,[1]재고!$F:$F,0),"") -> 0 | J16: =I16*H16 -> 0 | K16: =ROUNDUP(N16,-3) -> 0 | L16: =H16*K16 -> 0 | O16: =IFERROR(_xlfn.XLOOKUP($G16,[1]재고!$D:$D,[1]재고!$E:$E,0),"") -> 0 | R16: =O16*H16+P16 -> 0 | S16: =L16-R16 -> 0 | T16: =N16/O16-1 -> #DIV/0!
A17: =IFERROR(_xlfn.XLOOKUP($G17,[1]재고!$D:$D,[1]재고!$A:$A,0),"") -> 0 | D17: =IFERROR(_xlfn.XLOOKUP($G17,[1]재고!$D:$D,[1]재고!$B:$B,0),"") -> 0 | E17: =IFERROR(_xlfn.XLOOKUP($G17,[1]재고!$D:$D,[1]재고!$C:$C,0),"") -> 0 | F17: =IFERROR(_xlfn.XLOOKUP($G17,[1]재고!$D:$D,[1]재고!$G:$G,0),"") -> 0 | I17: =IFERROR(_xlfn.XLOOKUP($G17,[1]재고!$D:$D,[1]재고!$F:$F,0),"") -> 0 | J17: =I17*H17 -> 0 | K17: =ROUNDUP(N17,-3) -> 0 | L17: =H17*K17 -> 0 | O17: =IFERROR(_xlfn.XLOOKUP($G17,[1]재고!$D:$D,[1]재고!$E:$E,0),"") -> 0 | R17: =O17*H17+P17 -> 0 | S17: =L17-R17 -> 0 | T17: =N17/O17-1 -> #DIV/0!
A18: =IFERROR(_xlfn.XLOOKUP($G18,[1]재고!$D:$D,[1]재고!$A:$A,0),"") -> 0 | D18: =IFERROR(_xlfn.XLOOKUP($G18,[1]재고!$D:$D,[1]재고!$B:$B,0),"") -> 0 | E18: =IFERROR(_xlfn.XLOOKUP($G18,[1]재고!$D:$D,[1]재고!$C:$C,0),"") -> 0 | F18: =IFERROR(_xlfn.XLOOKUP($G18,[1]재고!$D:$D,[1]재고!$G:$G,0),"") -> 0 | I18: =IFERROR(_xlfn.XLOOKUP($G18,[1]재고!$D:$D,[1]재고!$F:$F,0),"") -> 0 | J18: =I18*H18 -> 0 | K18: =ROUNDUP(N18,-3) -> 0 | L18: =H18*K18 -> 0 | O18: =IFERROR(_xlfn.XLOOKUP($G18,[1]재고!$D:$D,[1]재고!$E:$E,0),"") -> 0 | R18: =O18*H18+P18 -> 0 | S18: =L18-R18 -> 0 | T18: =N18/O18-1 -> #DIV/0!
A19: =IFERROR(_xlfn.XLOOKUP($G19,[1]재고!$D:$D,[1]재고!$A:$A,0),"") -> 0 | D19: =IFERROR(_xlfn.XLOOKUP($G19,[1]재고!$D:$D,[1]재고!$B:$B,0),"") -> 0 | E19: =IFERROR(_xlfn.XLOOKUP($G19,[1]재고!$D:$D,[1]재고!$C:$C,0),"") -> 0 | F19: =IFERROR(_xlfn.XLOOKUP($G19,[1]재고!$D:$D,[1]재고!$G:$G,0),"") -> 0 | I19: =IFERROR(_xlfn.XLOOKUP($G19,[1]재고!$D:$D,[1]재고!$F:$F,0),"") -> 0 | J19: =I19*H19 -> 0 | K19: =ROUNDUP(N19,-3) -> 0 | L19: =H19*K19 -> 0 | O19: =IFERROR(_xlfn.XLOOKUP($G19,[1]재고!$D:$D,[1]재고!$E:$E,0),"") -> 0 | R19: =O19*H19+P19 -> 0 | S19: =L19-R19 -> 0 | T19: =N19/O19-1 -> #DIV/0!
A20: =IFERROR(_xlfn.XLOOKUP($G20,[1]재고!$D:$D,[1]재고!$A:$A,0),"") -> 0 | D20: =IFERROR(_xlfn.XLOOKUP($G20,[1]재고!$D:$D,[1]재고!$B:$B,0),"") -> 0 | E20: =IFERROR(_xlfn.XLOOKUP($G20,[1]재고!$D:$D,[1]재고!$C:$C,0),"") -> 0 | F20: =IFERROR(_xlfn.XLOOKUP($G20,[1]재고!$D:$D,[1]재고!$G:$G,0),"") -> 0 | I20: =IFERROR(_xlfn.XLOOKUP($G20,[1]재고!$D:$D,[1]재고!$F:$F,0),"") -> 0 | J20: =I20*H20 -> 0 | K20: =ROUNDUP(N20,-3) -> 0 | L20: =H20*K20 -> 0 | O20: =IFERROR(_xlfn.XLOOKUP($G20,[1]재고!$D:$D,[1]재고!$E:$E,0),"") -> 0 | R20: =O20*H20+P20 -> 0 | S20: =L20-R20 -> 0 | T20: =N20/O20-1 -> #DIV/0!
A21: =IFERROR(_xlfn.XLOOKUP($G21,[1]재고!$D:$D,[1]재고!$A:$A,0),"") -> 0 | D21: =IFERROR(_xlfn.XLOOKUP($G21,[1]재고!$D:$D,[1]재고!$B:$B,0),"") -> 0 | E21: =IFERROR(_xlfn.XLOOKUP($G21,[1]재고!$D:$D,[1]재고!$C:$C,0),"") -> 0 | F21: =IFERROR(_xlfn.XLOOKUP($G21,[1]재고!$D:$D,[1]재고!$G:$G,0),"") -> 0 | I21: =IFERROR(_xlfn.XLOOKUP($G21,[1]재고!$D:$D,[1]재고!$F:$F,0),"") -> 0 | J21: =I21*H21 -> 0 | K21: =ROUNDUP(N21,-3) -> 0 | L21: =H21*K21 -> 0 | O21: =IFERROR(_xlfn.XLOOKUP($G21,[1]재고!$D:$D,[1]재고!$E:$E,0),"") -> 0 | R21: =O21*H21+P21 -> 0 | S21: =L21-R21 -> 0 | T21: =N21/O21-1 -> #DIV/0!
A22: =IFERROR(_xlfn.XLOOKUP($G22,[1]재고!$D:$D,[1]재고!$A:$A,0),"") -> 0 | D22: =IFERROR(_xlfn.XLOOKUP($G22,[1]재고!$D:$D,[1]재고!$B:$B,0),"") -> 0 | E22: =IFERROR(_xlfn.XLOOKUP($G22,[1]재고!$D:$D,[1]재고!$C:$C,0),"") -> 0 | F22: =IFERROR(_xlfn.XLOOKUP($G22,[1]재고!$D:$D,[1]재고!$G:$G,0),"") -> 0 | I22: =IFERROR(_xlfn.XLOOKUP($G22,[1]재고!$D:$D,[1]재고!$F:$F,0),"") -> 0 | J22: =I22*H22 -> 0 | K22: =ROUNDUP(N22,-3) -> 0 | L22: =H22*K22 -> 0 | O22: =IFERROR(_xlfn.XLOOKUP($G22,[1]재고!$D:$D,[1]재고!$E:$E,0),"") -> 0 | R22: =O22*H22+P22 -> 0 | S22: =L22-R22 -> 0 | T22: =N22/O22-1 -> #DIV/0!
A23: =IFERROR(_xlfn.XLOOKUP($G23,[1]재고!$D:$D,[1]재고!$A:$A,0),"") -> 0 | D23: =IFERROR(_xlfn.XLOOKUP($G23,[1]재고!$D:$D,[1]재고!$B:$B,0),"") -> 0 | E23: =IFERROR(_xlfn.XLOOKUP($G23,[1]재고!$D:$D,[1]재고!$C:$C,0),"") -> 0 | F23: =IFERROR(_xlfn.XLOOKUP($G23,[1]재고!$D:$D,[1]재고!$G:$G,0),"") -> 0 | I23: =IFERROR(_xlfn.XLOOKUP($G23,[1]재고!$D:$D,[1]재고!$F:$F,0),"") -> 0 | J23: =I23*H23 -> 0 | K23: =ROUNDUP(N23,-3) -> 0 | L23: =H23*K23 -> 0 | O23: =IFERROR(_xlfn.XLOOKUP($G23,[1]재고!$D:$D,[1]재고!$E:$E,0),"") -> 0 | R23: =O23*H23+P23 -> 0 | S23: =L23-R23 -> 0 | T23: =N23/O23-1 -> #DIV/0!
A24: =IFERROR(_xlfn.XLOOKUP($G24,[1]재고!$D:$D,[1]재고!$A:$A,0),"") -> 0 | D24: =IFERROR(_xlfn.XLOOKUP($G24,[1]재고!$D:$D,[1]재고!$B:$B,0),"") -> 0 | E24: =IFERROR(_xlfn.XLOOKUP($G24,[1]재고!$D:$D,[1]재고!$C:$C,0),"") -> 0 | F24: =IFERROR(_xlfn.XLOOKUP($G24,[1]재고!$D:$D,[1]재고!$G:$G,0),"") -> 0 | I24: =IFERROR(_xlfn.XLOOKUP($G24,[1]재고!$D:$D,[1]재고!$F:$F,0),"") -> 0 | J24: =I24*H24 -> 0 | K24: =ROUNDUP(N24,-3) -> 0 | L24: =H24*K24 -> 0 | O24: =IFERROR(_xlfn.XLOOKUP($G24,[1]재고!$D:$D,[1]재고!$E:$E,0),"") -> 0 | R24: =O24*H24+P24 -> 0 | S24: =L24-R24 -> 0 | T24: =N24/O24-1 -> #DIV/0!
A25: =IFERROR(_xlfn.XLOOKUP($G25,[1]재고!$D:$D,[1]재고!$A:$A,0),"") -> 0 | D25: =IFERROR(_xlfn.XLOOKUP($G25,[1]재고!$D:$D,[1]재고!$B:$B,0),"") -> 0 | E25: =IFERROR(_xlfn.XLOOKUP($G25,[1]재고!$D:$D,[1]재고!$C:$C,0),"") -> 0 | F25: =IFERROR(_xlfn.XLOOKUP($G25,[1]재고!$D:$D,[1]재고!$G:$G,0),"") -> 0 | I25: =IFERROR(_xlfn.XLOOKUP($G25,[1]재고!$D:$D,[1]재고!$F:$F,0),"") -> 0 | J25: =I25*H25 -> 0 | K25: =ROUNDUP(N25,-3) -> 0 | L25: =H25*K25 -> 0 | O25: =IFERROR(_xlfn.XLOOKUP($G25,[1]재고!$D:$D,[1]재고!$E:$E,0),"") -> 0 | R25: =O25*H25+P25 -> 0 | S25: =L25-R25 -> 0 | T25: =N25/O25-1 -> #DIV/0!
... A28: =IFERROR(_xlfn.XLOOKUP($G28,[1]재고!$D:$D,[1]재고!$A:$A,0),"") -> 0 | D28: =IFERROR(_xlfn.XLOOKUP($G28,[1]재고!$D:$D,[1]재고!$B:$B,0),"") -> 0 | E28: =IFERROR(_xlfn.XLOOKUP($G28,[1]재고!$D:$D,[1]재고!$C:$C,0),"") -> 0 | F28: =IFERROR(_xlfn.XLOOKUP($G28,[1]재고!$D:$D,[1]재고!$G:$G,0),"") -> 0 | I28: =IFERROR(_xlfn.XLOOKUP($G28,[1]재고!$D:$D,[1]재고!$F:$F,0),"") -> 0 | J28: =I28*H28 -> 0 | K28: =ROUNDUP(N28,-3) -> 0 | L28: =H28*K28 -> 0 | O28: =IFERROR(_xlfn.XLOOKUP($G28,[1]재고!$D:$D,[1]재고!$E:$E,0),"") -> 0 | R28: =O28*H28+P28 -> 0 | S28: =L28-R28 -> 0 | T28: =N28/O28-1 -> #DIV/0!
A29: =IFERROR(_xlfn.XLOOKUP($F29,[1]재고!$D:$D,[1]재고!$A:$A,0),"") -> 0 | D29: =IFERROR(_xlfn.XLOOKUP($G29,[1]재고!$D:$D,[1]재고!$B:$B,0),"") -> 0 | E29: =IFERROR(_xlfn.XLOOKUP($G29,[1]재고!$D:$D,[1]재고!$C:$C,0),"") -> 0 | F29: =IFERROR(_xlfn.XLOOKUP($G29,[1]재고!$D:$D,[1]재고!$G:$G,0),"") -> 0 | I29: =IFERROR(_xlfn.XLOOKUP($G29,[1]재고!$D:$D,[1]재고!$F:$F,0),"") -> 0 | J29: =I29*H29 -> 0 | K29: =ROUNDUP(N29,-3) -> 0 | L29: =H29*K29 -> 0 | O29: =IFERROR(_xlfn.XLOOKUP($F29,[1]재고!$D:$D,[1]재고!$E:$E,0),"") -> 0 | R29: =O29*H29+P29 -> 0 | S29: =L29-R29 -> 0 | T29: =N29/O29-1 -> #DIV/0!
D30: 합계 | I30: =SUM(J14:J29) -> 0 | K30: (부가세포함) | L30: =SUM(L14:L29) -> 0 | R30: =SUM(R14:R29) -> 0 | S30: =SUM(S14:S29) -> 0 | T30: =S30/L30 -> #DIV/0!
K31: 카드결제 +4% | L31: =L30*1.04 -> 0
D32: 담당 | F32: 전인철 실장 010-4311-3604 | I32: 결제 방식 | K32: 현금영수증 / 세금계산서
D33: 배송방식 | F33: 택배 발송 | I33: 납품일자 | K33: 협의후 진행
C35: - 위 견적은 일주일간 유효하며 이후 금액이 변동될 수 있습니다. - 현금가 기준이며, 카드결제시 4% 수수료 추가됩니다. - 타 업체에 해당 견적서 유출을 방지해 주시기 바랍니다. - 견적중 일부 상품만 구매시 금액이 변동될 수 있습니다.
C36: 계좌정보: 우리은행(1005-804-509027) (주)비에스비인터내셔널

Sheet 유효성데이터
B1: FILTER([퍼커션센터_통합_매출기록부.xlsx]재고!$D$4:$D$6000,ISNUMBER(SEARCH(MAIN!M10,[퍼커션센터_통합_매출기록부.xlsx]재고!$D$4:$D$6000)))
B2: 유효성목록
B3: {=_xlfn._xlws.FILTER([1]재고!$D$4:$D$7955,ISNUMBER(SEARCH(MAIN!O10,[1]재고!$D$4:$D$7955)))} -> CP404BLK
B4: CP404RED
B5: CP430
B6: CP5003
B7: CP5230
B8: CP5901
B9: CP80 (중앙악기)
B10: CP85 (중앙악기)
B11: CP90 (중앙악기)
B12: CP91 (중앙악기)
B13: CP404BLK (중앙악기)
B14: CP404RED (중앙악기)
B15: CP5002 (중앙악기)
... B854: 696201
B855: 696240
B856: 696241
B857: ALLN1PAD13
B858: BF-PP12RMB
B859: BF-PPS8RGB
B860: VXPPVF06
B861: VXPPVF12
B862: VXPPDC12
B863: BF-PPS6OB
B864: BPADSET
B865: ZXPPRCP10
B866: ZXPPGRA12
B867: ZXPPGAL12
B868: ZXSB00102
... B1222: RM2
B1223: 61368
B1224: TX7AW-AG
B1225: R5AFG
B1226: ATH-M20X
B1227: ATH-M50X
B1228: SG5000 헤드폰
B1229: LS5000
B1230: DT770 pro 80옴
B1231: DT770 pro 250옴
...
